Traceback (most recent call last):
  File "C:\Users\kovor\anaconda3\envs\py3.7\lib\site-packages\jupyter_cache\executors\utils.py", line 51, in single_nb_execution
    executenb(
  File "C:\Users\kovor\anaconda3\envs\py3.7\lib\site-packages\nbclient\client.py", line 1204, in execute
    return NotebookClient(nb=nb, resources=resources, km=km, **kwargs).execute()
  File "C:\Users\kovor\anaconda3\envs\py3.7\lib\site-packages\nbclient\util.py", line 84, in wrapped
    return just_run(coro(*args, **kwargs))
  File "C:\Users\kovor\anaconda3\envs\py3.7\lib\site-packages\nbclient\util.py", line 62, in just_run
    return loop.run_until_complete(coro)
  File "C:\Users\kovor\anaconda3\envs\py3.7\lib\asyncio\base_events.py", line 646, in run_until_complete
    return future.result()
  File "C:\Users\kovor\anaconda3\envs\py3.7\lib\site-packages\nbclient\client.py", line 663, in async_execute
    await self.async_execute_cell(
  File "C:\Users\kovor\anaconda3\envs\py3.7\lib\site-packages\nbclient\client.py", line 965, in async_execute_cell
    await self._check_raise_for_error(cell, cell_index, exec_reply)
  File "C:\Users\kovor\anaconda3\envs\py3.7\lib\site-packages\nbclient\client.py", line 862, in _check_raise_for_error
    raise CellExecutionError.from_cell_and_msg(cell, exec_reply_content)
nbclient.exceptions.CellExecutionError: An error occurred while executing the following cell:
------------------
from matplotlib import rcParams, cycler
import matplotlib.pyplot as plt
import numpy as np
plt.ion()
------------------

[1;31m---------------------------------------------------------------------------[0m
[1;31mImportError[0m                               Traceback (most recent call last)
[1;32m~\Anaconda3\lib\site-packages\numpy\core\__init__.py[0m in [0;36m<module>[1;34m[0m
[0;32m     21[0m [1;32mtry[0m[1;33m:[0m[1;33m[0m[1;33m[0m[0m
[1;32m---> 22[1;33m     [1;32mfrom[0m [1;33m.[0m [1;32mimport[0m [0mmultiarray[0m[1;33m[0m[1;33m[0m[0m
[0m[0;32m     23[0m [1;32mexcept[0m [0mImportError[0m [1;32mas[0m [0mexc[0m[1;33m:[0m[1;33m[0m[1;33m[0m[0m

[1;32m~\Anaconda3\lib\site-packages\numpy\core\multiarray.py[0m in [0;36m<module>[1;34m[0m
[0;32m     11[0m [1;33m[0m[0m
[1;32m---> 12[1;33m [1;32mfrom[0m [1;33m.[0m [1;32mimport[0m [0moverrides[0m[1;33m[0m[1;33m[0m[0m
[0m[0;32m     13[0m [1;32mfrom[0m [1;33m.[0m [1;32mimport[0m [0m_multiarray_umath[0m[1;33m[0m[1;33m[0m[0m

[1;32m~\Anaconda3\lib\site-packages\numpy\core\overrides.py[0m in [0;36m<module>[1;34m[0m
[0;32m      6[0m [1;33m[0m[0m
[1;32m----> 7[1;33m from numpy.core._multiarray_umath import (
[0m[0;32m      8[0m     add_docstring, implement_array_function, _get_implementing_args)

[1;31mImportError[0m: DLL load failed while importing _multiarray_umath: The specified module could not be found.

During handling of the above exception, another exception occurred:

[1;31mImportError[0m                               Traceback (most recent call last)
[1;32m~\AppData\Local\Temp/ipykernel_17064/2191868119.py[0m in [0;36m<module>[1;34m[0m
[1;32m----> 1[1;33m [1;32mfrom[0m [0mmatplotlib[0m [1;32mimport[0m [0mrcParams[0m[1;33m,[0m [0mcycler[0m[1;33m[0m[1;33m[0m[0m
[0m[0;32m      2[0m [1;32mimport[0m [0mmatplotlib[0m[1;33m.[0m[0mpyplot[0m [1;32mas[0m [0mplt[0m[1;33m[0m[1;33m[0m[0m
[0;32m      3[0m [1;32mimport[0m [0mnumpy[0m [1;32mas[0m [0mnp[0m[1;33m[0m[1;33m[0m[0m
[0;32m      4[0m [0mplt[0m[1;33m.[0m[0mion[0m[1;33m([0m[1;33m)[0m[1;33m[0m[1;33m[0m[0m

[1;32m~\Anaconda3\lib\site-packages\matplotlib\__init__.py[0m in [0;36m<module>[1;34m[0m
[0;32m    105[0m [1;31m# cbook must import matplotlib only within function[0m[1;33m[0m[1;33m[0m[0m
[0;32m    106[0m [1;31m# definitions, so it is safe to import from it here.[0m[1;33m[0m[1;33m[0m[0m
[1;32m--> 107[1;33m [1;32mfrom[0m [1;33m.[0m [1;32mimport[0m [0m_api[0m[1;33m,[0m [0mcbook[0m[1;33m,[0m [0mdocstring[0m[1;33m,[0m [0mrcsetup[0m[1;33m[0m[1;33m[0m[0m
[0m[0;32m    108[0m [1;32mfrom[0m [0mmatplotlib[0m[1;33m.[0m[0mcbook[0m [1;32mimport[0m [0mMatplotlibDeprecationWarning[0m[1;33m,[0m [0msanitize_sequence[0m[1;33m[0m[1;33m[0m[0m
[0;32m    109[0m [1;32mfrom[0m [0mmatplotlib[0m[1;33m.[0m[0mcbook[0m [1;32mimport[0m [0mmplDeprecation[0m  [1;31m# deprecated[0m[1;33m[0m[1;33m[0m[0m

[1;32m~\Anaconda3\lib\site-packages\matplotlib\cbook\__init__.py[0m in [0;36m<module>[1;34m[0m
[0;32m     26[0m [1;32mimport[0m [0mweakref[0m[1;33m[0m[1;33m[0m[0m
[0;32m     27[0m [1;33m[0m[0m
[1;32m---> 28[1;33m [1;32mimport[0m [0mnumpy[0m [1;32mas[0m [0mnp[0m[1;33m[0m[1;33m[0m[0m
[0m[0;32m     29[0m [1;33m[0m[0m
[0;32m     30[0m [1;32mimport[0m [0mmatplotlib[0m[1;33m[0m[1;33m[0m[0m

[1;32m~\Anaconda3\lib\site-packages\numpy\__init__.py[0m in [0;36m<module>[1;34m[0m
[0;32m    143[0m     [1;32mfrom[0m [1;33m.[0m [1;32mimport[0m [0m_distributor_init[0m[1;33m[0m[1;33m[0m[0m
[0;32m    144[0m [1;33m[0m[0m
[1;32m--> 145[1;33m     [1;32mfrom[0m [1;33m.[0m [1;32mimport[0m [0mcore[0m[1;33m[0m[1;33m[0m[0m
[0m[0;32m    146[0m     [1;32mfrom[0m [1;33m.[0m[0mcore[0m [1;32mimport[0m [1;33m*[0m[1;33m[0m[1;33m[0m[0m
[0;32m    147[0m     [1;32mfrom[0m [1;33m.[0m [1;32mimport[0m [0mcompat[0m[1;33m[0m[1;33m[0m[0m

[1;32m~\Anaconda3\lib\site-packages\numpy\core\__init__.py[0m in [0;36m<module>[1;34m[0m
[0;32m     46[0m """ % (sys.version_info[0], sys.version_info[1], sys.executable,
[0;32m     47[0m         __version__, exc)
[1;32m---> 48[1;33m     [1;32mraise[0m [0mImportError[0m[1;33m([0m[0mmsg[0m[1;33m)[0m[1;33m[0m[1;33m[0m[0m
[0m[0;32m     49[0m [1;32mfinally[0m[1;33m:[0m[1;33m[0m[1;33m[0m[0m
[0;32m     50[0m     [1;32mfor[0m [0menvkey[0m [1;32min[0m [0menv_added[0m[1;33m:[0m[1;33m[0m[1;33m[0m[0m

[1;31mImportError[0m: 

IMPORTANT: PLEASE READ THIS FOR ADVICE ON HOW TO SOLVE THIS ISSUE!

Importing the numpy C-extensions failed. This error can happen for
many reasons, often due to issues with your setup or how NumPy was
installed.

We have compiled some common reasons and troubleshooting tips at:

    https://numpy.org/devdocs/user/troubleshooting-importerror.html

Please note and check the following:

  * The Python version is: Python3.9 from "C:\Users\kovor\Anaconda3\python.exe"
  * The NumPy version is: "1.20.3"

and make sure that they are the versions you expect.
Please carefully study the documentation linked above for further help.

Original error was: DLL load failed while importing _multiarray_umath: The specified module could not be found.

ImportError: 

IMPORTANT: PLEASE READ THIS FOR ADVICE ON HOW TO SOLVE THIS ISSUE!

Importing the numpy C-extensions failed. This error can happen for
many reasons, often due to issues with your setup or how NumPy was
installed.

We have compiled some common reasons and troubleshooting tips at:

    https://numpy.org/devdocs/user/troubleshooting-importerror.html

Please note and check the following:

  * The Python version is: Python3.9 from "C:\Users\kovor\Anaconda3\python.exe"
  * The NumPy version is: "1.20.3"

and make sure that they are the versions you expect.
Please carefully study the documentation linked above for further help.

Original error was: DLL load failed while importing _multiarray_umath: The specified module could not be found.


